[2025-04-06T08:50:26.174+0000] {local_task_job_runner.py:123} INFO - ::group::Pre task execution logs
[2025-04-06T08:50:26.201+0000] {taskinstance.py:2614} INFO - Dependencies all met for dep_context=non-requeueable deps ti=<TaskInstance: etl_dbt_spark_oracle.dbt_run scheduled__2025-04-05T00:00:00+00:00 [queued]>
[2025-04-06T08:50:26.220+0000] {taskinstance.py:2614} INFO - Dependencies all met for dep_context=requeueable deps ti=<TaskInstance: etl_dbt_spark_oracle.dbt_run scheduled__2025-04-05T00:00:00+00:00 [queued]>
[2025-04-06T08:50:26.221+0000] {taskinstance.py:2867} INFO - Starting attempt 1 of 1
[2025-04-06T08:50:26.484+0000] {taskinstance.py:2890} INFO - Executing <Task(BashOperator): dbt_run> on 2025-04-05 00:00:00+00:00
[2025-04-06T08:50:26.498+0000] {warnings.py:112} WARNING - /home/***/.local/lib/python3.12/site-packages/***/task/task_runner/standard_task_runner.py:70: DeprecationWarning: This process (pid=67) is multi-threaded, use of fork() may lead to deadlocks in the child.
  pid = os.fork()

[2025-04-06T08:50:26.501+0000] {standard_task_runner.py:72} INFO - Started process 71 to run task
[2025-04-06T08:50:26.503+0000] {standard_task_runner.py:104} INFO - Running: ['***', 'tasks', 'run', 'etl_dbt_spark_oracle', 'dbt_run', 'scheduled__2025-04-05T00:00:00+00:00', '--job-id', '39', '--raw', '--subdir', 'DAGS_FOLDER/dbt-spark-oracle.py', '--cfg-path', '/tmp/tmpo240_hgw']
[2025-04-06T08:50:26.509+0000] {standard_task_runner.py:105} INFO - Job 39: Subtask dbt_run
[2025-04-06T08:50:26.616+0000] {task_command.py:467} INFO - Running <TaskInstance: etl_dbt_spark_oracle.dbt_run scheduled__2025-04-05T00:00:00+00:00 [running]> on host b1934a8bdc93
[2025-04-06T08:50:26.803+0000] {taskinstance.py:3134} INFO - Exporting env vars: AIRFLOW_CTX_DAG_OWNER='***' AIRFLOW_CTX_DAG_ID='etl_dbt_spark_oracle' AIRFLOW_CTX_TASK_ID='dbt_run' AIRFLOW_CTX_EXECUTION_DATE='2025-04-05T00:00:00+00:00' AIRFLOW_CTX_TRY_NUMBER='1' AIRFLOW_CTX_DAG_RUN_ID='scheduled__2025-04-05T00:00:00+00:00'
[2025-04-06T08:50:26.806+0000] {logging_mixin.py:190} INFO - Task instance is in running state
[2025-04-06T08:50:26.807+0000] {logging_mixin.py:190} INFO -  Previous state of the Task instance: queued
[2025-04-06T08:50:26.808+0000] {logging_mixin.py:190} INFO - Current task name:dbt_run state:running start_date:2025-04-06 08:50:26.202912+00:00
[2025-04-06T08:50:26.809+0000] {logging_mixin.py:190} INFO - Dag name:etl_dbt_spark_oracle and current dag run status:running
[2025-04-06T08:50:26.810+0000] {taskinstance.py:732} INFO - ::endgroup::
[2025-04-06T08:50:26.813+0000] {subprocess.py:78} INFO - Tmp dir root location: /tmp
[2025-04-06T08:50:26.816+0000] {subprocess.py:88} INFO - Running command: ['/usr/bin/bash', '-c', 'cd /dbt/dbt-spark-project && /opt/spark/sbin/start-thriftserver.sh --master local[*] --hiveconf hive.metastore.warehouse.dir=/opt/spark/spark-warehouse --hiveconf javax.jdo.option.ConnectionURL="jdbc:derby:;databaseName=/opt/spark/metastore_db;create=true" && sleep 10 && dbt run']
[2025-04-06T08:50:26.842+0000] {subprocess.py:99} INFO - Output:
[2025-04-06T08:50:26.876+0000] {subprocess.py:106} INFO - /opt/spark/bin/load-spark-env.sh: line 68: ps: command not found
[2025-04-06T08:50:26.885+0000] {subprocess.py:106} INFO - mkdir: cannot create directory â€˜/opt/spark/logsâ€™: Permission denied
[2025-04-06T08:50:26.893+0000] {subprocess.py:106} INFO - chown: cannot access '/opt/spark/logs': No such file or directory
[2025-04-06T08:50:26.897+0000] {subprocess.py:106} INFO - starting org.apache.spark.sql.hive.thriftserver.HiveThriftServer2, logging to /opt/spark/logs/spark--org.apache.spark.sql.hive.thriftserver.HiveThriftServer2-1-b1934a8bdc93.out
[2025-04-06T08:50:26.898+0000] {subprocess.py:106} INFO - /opt/spark/sbin/spark-daemon.sh: line 135: /opt/spark/logs/spark--org.apache.spark.sql.hive.thriftserver.HiveThriftServer2-1-b1934a8bdc93.out: No such file or directory
[2025-04-06T08:50:26.899+0000] {subprocess.py:106} INFO - /opt/spark/sbin/spark-daemon.sh: line 143: ps: command not found
[2025-04-06T08:50:27.406+0000] {subprocess.py:106} INFO - /opt/spark/sbin/spark-daemon.sh: line 143: ps: command not found
[2025-04-06T08:50:27.918+0000] {subprocess.py:106} INFO - /opt/spark/sbin/spark-daemon.sh: line 143: ps: command not found
[2025-04-06T08:50:28.425+0000] {subprocess.py:106} INFO - /opt/spark/sbin/spark-daemon.sh: line 143: ps: command not found
[2025-04-06T08:50:28.937+0000] {subprocess.py:106} INFO - /opt/spark/sbin/spark-daemon.sh: line 143: ps: command not found
[2025-04-06T08:50:29.451+0000] {subprocess.py:106} INFO - /opt/spark/sbin/spark-daemon.sh: line 143: ps: command not found
[2025-04-06T08:50:29.965+0000] {subprocess.py:106} INFO - /opt/spark/sbin/spark-daemon.sh: line 143: ps: command not found
[2025-04-06T08:50:30.492+0000] {subprocess.py:106} INFO - /opt/spark/sbin/spark-daemon.sh: line 143: ps: command not found
[2025-04-06T08:50:30.995+0000] {subprocess.py:106} INFO - /opt/spark/sbin/spark-daemon.sh: line 143: ps: command not found
[2025-04-06T08:50:31.500+0000] {subprocess.py:106} INFO - /opt/spark/sbin/spark-daemon.sh: line 143: ps: command not found
[2025-04-06T08:50:34.007+0000] {subprocess.py:106} INFO - /opt/spark/sbin/spark-daemon.sh: line 151: ps: command not found
[2025-04-06T08:50:34.007+0000] {subprocess.py:106} INFO - failed to launch: nice -n 0 bash /opt/spark/bin/spark-submit --class org.apache.spark.sql.hive.thriftserver.HiveThriftServer2 --name Thrift JDBC/ODBC Server --master local[*] --hiveconf hive.metastore.warehouse.dir=/opt/spark/spark-warehouse --hiveconf javax.jdo.option.ConnectionURL=jdbc:derby:;databaseName=/opt/spark/metastore_db;create=true
[2025-04-06T08:50:34.011+0000] {subprocess.py:106} INFO - tail: cannot open '/opt/spark/logs/spark--org.apache.spark.sql.hive.thriftserver.HiveThriftServer2-1-b1934a8bdc93.out' for reading: No such file or directory
[2025-04-06T08:50:34.014+0000] {subprocess.py:106} INFO - full log in /opt/spark/logs/spark--org.apache.spark.sql.hive.thriftserver.HiveThriftServer2-1-b1934a8bdc93.out
[2025-04-06T08:50:48.944+0000] {subprocess.py:106} INFO - [0m08:50:48  Running with dbt=1.9.3
[2025-04-06T08:50:49.031+0000] {subprocess.py:106} INFO - WARNING:thrift.transport.sslcompat:using legacy validation callback
[2025-04-06T08:50:49.717+0000] {subprocess.py:106} INFO - [0m08:50:49  Registered adapter: spark=1.9.2
[2025-04-06T08:50:51.603+0000] {subprocess.py:106} INFO - [0m08:50:51  [[33mWARNING[0m]: Configuration paths exist in your dbt_project.yml file which do not apply to any resources.
[2025-04-06T08:50:51.604+0000] {subprocess.py:106} INFO - There are 1 unused configuration paths:
[2025-04-06T08:50:51.605+0000] {subprocess.py:106} INFO - - models.dbt_spark_project.example
[2025-04-06T08:50:51.955+0000] {subprocess.py:106} INFO - [0m08:50:51  Found 6 models, 1 source, 473 macros
[2025-04-06T08:50:51.962+0000] {subprocess.py:106} INFO - [0m08:50:51
[2025-04-06T08:50:51.963+0000] {subprocess.py:106} INFO - [0m08:50:51  Concurrency: 1 threads (target='dev')
[2025-04-06T08:50:51.964+0000] {subprocess.py:106} INFO - [0m08:50:51
[2025-04-06T08:50:52.012+0000] {subprocess.py:106} INFO - [0m08:50:52  Could not connect to any of [('::1', 10000, 0, 0), ('127.0.0.1', 10000)]
[2025-04-06T08:50:52.013+0000] {subprocess.py:106} INFO - ERROR:thrift.transport.TSocket:Could not connect to any of [('::1', 10000, 0, 0), ('127.0.0.1', 10000)]
[2025-04-06T08:50:52.020+0000] {subprocess.py:106} INFO - [0m08:50:52
[2025-04-06T08:50:52.022+0000] {subprocess.py:106} INFO - [0m08:50:52  Finished running  in 0 hours 0 minutes and 0.06 seconds (0.06s).
[2025-04-06T08:50:52.023+0000] {subprocess.py:106} INFO - [0m08:50:52  Encountered an error:
[2025-04-06T08:50:52.024+0000] {subprocess.py:106} INFO - Runtime Error
[2025-04-06T08:50:52.025+0000] {subprocess.py:106} INFO -   Runtime Error
[2025-04-06T08:50:52.028+0000] {subprocess.py:106} INFO -     Database Error
[2025-04-06T08:50:52.029+0000] {subprocess.py:106} INFO -       failed to connect
[2025-04-06T08:50:52.777+0000] {subprocess.py:110} INFO - Command exited with return code 2
[2025-04-06T08:50:52.803+0000] {taskinstance.py:3313} ERROR - Task failed with exception
Traceback (most recent call last):
  File "/home/airflow/.local/lib/python3.12/site-packages/airflow/models/taskinstance.py", line 768, in _execute_task
    result = _execute_callable(context=context, **execute_callable_kwargs)
             ^^^^^^^^^^^^^^^^^^^^^^^^^^^^^^^^^^^^^^^^^^^^^^^^^^^^^^^^^^^^^
  File "/home/airflow/.local/lib/python3.12/site-packages/airflow/models/taskinstance.py", line 734, in _execute_callable
    return ExecutionCallableRunner(
           ^^^^^^^^^^^^^^^^^^^^^^^^
  File "/home/airflow/.local/lib/python3.12/site-packages/airflow/utils/operator_helpers.py", line 252, in run
    return self.func(*args, **kwargs)
           ^^^^^^^^^^^^^^^^^^^^^^^^^^
  File "/home/airflow/.local/lib/python3.12/site-packages/airflow/models/baseoperator.py", line 424, in wrapper
    return func(self, *args, **kwargs)
           ^^^^^^^^^^^^^^^^^^^^^^^^^^^
  File "/home/airflow/.local/lib/python3.12/site-packages/airflow/operators/bash.py", line 276, in execute
    raise AirflowException(
airflow.exceptions.AirflowException: Bash command failed. The command returned a non-zero exit code 2.
[2025-04-06T08:50:52.813+0000] {logging_mixin.py:190} INFO - Task instance in failure state
[2025-04-06T08:50:52.814+0000] {logging_mixin.py:190} INFO - Task start:2025-04-06 08:50:26.202912+00:00 end:2025-04-06 08:50:52.812346+00:00 duration:26.609434
[2025-04-06T08:50:52.815+0000] {logging_mixin.py:190} INFO - Task:<Task(BashOperator): dbt_run> dag:<DAG: etl_dbt_spark_oracle> dagrun:<DagRun etl_dbt_spark_oracle @ 2025-04-05 00:00:00+00:00: scheduled__2025-04-05T00:00:00+00:00, state:running, queued_at: 2025-04-06 08:50:08.952503+00:00. externally triggered: False>
[2025-04-06T08:50:52.816+0000] {logging_mixin.py:190} INFO - Failure caused by Bash command failed. The command returned a non-zero exit code 2.
[2025-04-06T08:50:52.817+0000] {taskinstance.py:1226} INFO - Marking task as FAILED. dag_id=etl_dbt_spark_oracle, task_id=dbt_run, run_id=scheduled__2025-04-05T00:00:00+00:00, execution_date=20250405T000000, start_date=20250406T085026, end_date=20250406T085052
[2025-04-06T08:50:52.883+0000] {taskinstance.py:341} INFO - ::group::Post task execution logs
[2025-04-06T08:50:52.886+0000] {standard_task_runner.py:124} ERROR - Failed to execute job 39 for task dbt_run (Bash command failed. The command returned a non-zero exit code 2.; 71)
Traceback (most recent call last):
  File "/home/airflow/.local/lib/python3.12/site-packages/airflow/task/task_runner/standard_task_runner.py", line 117, in _start_by_fork
    ret = args.func(args, dag=self.dag)
          ^^^^^^^^^^^^^^^^^^^^^^^^^^^^^
  File "/home/airflow/.local/lib/python3.12/site-packages/airflow/cli/cli_config.py", line 49, in command
    return func(*args, **kwargs)
           ^^^^^^^^^^^^^^^^^^^^^
  File "/home/airflow/.local/lib/python3.12/site-packages/airflow/utils/cli.py", line 116, in wrapper
    return f(*args, **kwargs)
           ^^^^^^^^^^^^^^^^^^
  File "/home/airflow/.local/lib/python3.12/site-packages/airflow/cli/commands/task_command.py", line 483, in task_run
    task_return_code = _run_task_by_selected_method(args, _dag, ti)
                       ^^^^^^^^^^^^^^^^^^^^^^^^^^^^^^^^^^^^^^^^^^^^
  File "/home/airflow/.local/lib/python3.12/site-packages/airflow/cli/commands/task_command.py", line 256, in _run_task_by_selected_method
    return _run_raw_task(args, ti)
           ^^^^^^^^^^^^^^^^^^^^^^^
  File "/home/airflow/.local/lib/python3.12/site-packages/airflow/cli/commands/task_command.py", line 341, in _run_raw_task
    return ti._run_raw_task(
           ^^^^^^^^^^^^^^^^^
  File "/home/airflow/.local/lib/python3.12/site-packages/airflow/utils/session.py", line 97, in wrapper
    return func(*args, session=session, **kwargs)
           ^^^^^^^^^^^^^^^^^^^^^^^^^^^^^^^^^^^^^^
  File "/home/airflow/.local/lib/python3.12/site-packages/airflow/models/taskinstance.py", line 3006, in _run_raw_task
    return _run_raw_task(
           ^^^^^^^^^^^^^^
  File "/home/airflow/.local/lib/python3.12/site-packages/airflow/models/taskinstance.py", line 274, in _run_raw_task
    TaskInstance._execute_task_with_callbacks(
  File "/home/airflow/.local/lib/python3.12/site-packages/airflow/models/taskinstance.py", line 3161, in _execute_task_with_callbacks
    result = self._execute_task(context, task_orig)
             ^^^^^^^^^^^^^^^^^^^^^^^^^^^^^^^^^^^^^^
  File "/home/airflow/.local/lib/python3.12/site-packages/airflow/models/taskinstance.py", line 3185, in _execute_task
    return _execute_task(self, context, task_orig)
           ^^^^^^^^^^^^^^^^^^^^^^^^^^^^^^^^^^^^^^^
  File "/home/airflow/.local/lib/python3.12/site-packages/airflow/models/taskinstance.py", line 768, in _execute_task
    result = _execute_callable(context=context, **execute_callable_kwargs)
             ^^^^^^^^^^^^^^^^^^^^^^^^^^^^^^^^^^^^^^^^^^^^^^^^^^^^^^^^^^^^^
  File "/home/airflow/.local/lib/python3.12/site-packages/airflow/models/taskinstance.py", line 734, in _execute_callable
    return ExecutionCallableRunner(
           ^^^^^^^^^^^^^^^^^^^^^^^^
  File "/home/airflow/.local/lib/python3.12/site-packages/airflow/utils/operator_helpers.py", line 252, in run
    return self.func(*args, **kwargs)
           ^^^^^^^^^^^^^^^^^^^^^^^^^^
  File "/home/airflow/.local/lib/python3.12/site-packages/airflow/models/baseoperator.py", line 424, in wrapper
    return func(self, *args, **kwargs)
           ^^^^^^^^^^^^^^^^^^^^^^^^^^^
  File "/home/airflow/.local/lib/python3.12/site-packages/airflow/operators/bash.py", line 276, in execute
    raise AirflowException(
airflow.exceptions.AirflowException: Bash command failed. The command returned a non-zero exit code 2.
[2025-04-06T08:50:52.911+0000] {local_task_job_runner.py:266} INFO - Task exited with return code 1
[2025-04-06T08:50:52.977+0000] {taskinstance.py:3901} INFO - 0 downstream tasks scheduled from follow-on schedule check
[2025-04-06T08:50:52.988+0000] {local_task_job_runner.py:245} INFO - ::endgroup::
